Workbook

Sheet Progress score
A1: The content of these columns is used to generate the PDF to be published (use the PDF export function in this software). | E1: Columns to help complete the ecodesign declaration (not published in the generated PDF)
A2: Ecodesign declaration of conformity SMART LIBRARY 15/11/2025 | E2: This spreadsheet has been produced to make it easier to draw up an ecodesign declaration, as part of the implementation of the general policy framework for the ecodesign of digital services (version 2024). It enables users to draw up their ecodesign declaration (a PDF export is available, which can be used as an ecodesign declaration) and to calculate the service's progress score. This .xlsx version (Office Open XML) is intended for Microsoft Excel, OnlyOffice, Google Sheets or Apple Numbers.
A3: The [to be completed] service implement an ecodesign approach aimed at reducing its environmental footprint. To this end, this declaration was drafted on [date to be completed], as part of the implementation of the General Policy Framework for the Ecodesign of Digital Services (2024 version). The General Policy Framework for the Ecodesign of Digital Services, a document produced by Arcep and Arcom in collaboration with ADEME, DINUM, CNIL and Inria, is available on the Arcep website. Its implementation has four main goals: 1) Design more sustainable digital services to extend devices’ lifespan; 2) Promote a mindset of striving for eco-sufficiency in response to online attention-grabbing strategies, to align with international environmental targets; 3) Decrease the IT resources mobilised over the digital service’s life cycle, including by optimising data traffic and digital infrastructure use; 4) Increase transparency on the digital service’s environmental footprint. | E3: If you use LibreOffice Calc, Collabora Office Calc, Calligra Sheets and Apache OpenOffice Calc, prefer the .ods (OpenDocument 1.3) version of this spreadsheet, available on https://www.arcep.fr/fileadmin/user_upload/nos-sujets/environnement/rgesn_2024_ecodesign_declaration_tool.ods The left-hand side (white or grey background) of each sheet corresponds to the content of a page when the PDF is generated. The text in square brackets on the ‘Progress Score’ sheet and the empty boxes on the following sheets must be filled in. This 14-page PDF is now ready for publication as an ecodesign declaration. The central part (dark yellow background) is outside the area used to generate the PDF. Some boxes are for internal use (‘Level of difficulty’, ‘Actions to be taken’, ‘Who does?’, ‘For when?’): you should only complete these boxes if it will help you to progress or complete the declaration. The right-hand side (light yellow background) contains boxes to help you assess the criteria, examples of ecodesign declarations or boxes giving information on the score awarded on the basis of the assessment completed in the left-hand section. These boxes are not published in the generated PDF.
E4: Instructions for generating the ecodesign declaration PDF with Microsoft Excel: In the "File" menu, click on "Export" then "Create PDF". In the window that appears, click on "Options...". There are 4 boxes to check: 1/ in "Content to publish": check the "Entire workbook" button to create a PDF with the 14 sheets of this document; 2/ in "Include non-printable information": check the "Structure tags for accessibility" box to make the PDF more accessible; 3/ in "PDF Option": check the "PDF/A compatible" box. Click on "OK", then on "Publish", the 14-page PDF is created, ready to be published.
B5: Name of service evaluated | C5: Smart Library
B6: Samples used to establish ecodesign diagnosis | C6: Project documentation, architecture diagrams, UI mock-ups, backend logic, and team technical notes
B7: Entity carrying out the valuation | C7: Student development team – Smart Library
B8: Name of the person responsible for this assessment | C8: Mintesnot Nigusu YIMER And Moeez Ahmed
B10: Global Progress Score | C10: =E11/F11 -> 0.62608696 | E10: Total score | F10: Total denominator
B11: Date of evaluation | C11: 15/11/2025 | E11: =SUM(E14:E22) -> 54 | F11: =SUM(F14:F22) -> 86.25
B13: Score by theme : | E13: Score by theme (total) | F13: Denominator by theme (total) | G13: Score by page (1) | H13: Score by page (2) | I13: Denominator by page (1) | J13: Denominator by page (2)
B14: 1 – Strategy (details page 2 and page 3) | C14: =IF(F14,E14/F14,"Not applicable") -> 0.92592593 | E14: =SUM(G14:H14) -> 12.5 | F14: =SUM(I14:J14) -> 13.5 | G14: ='1 Strategy (1)'!L3+'1 Strategy (1)'!L5+'1 Strategy (1)'!L7+'1 Strategy (1)'!L9+'1 Strategy (1)'!L11 -> 7.25 | H14: ='1 Strategy (2)'!L3+'1 Strategy (2)'!L5+'1 Strategy (2)'!L7+'1 Strategy (2)'!L9+'1 Strategy (2)'!L11 -> 5.25 | I14: ='1 Strategy (1)'!M3+'1 Strategy (1)'!M5+'1 Strategy (1)'!M7+'1 Strategy (1)'!M9+'1 Strategy (1)'!M11 -> 7.25 | J14: ='1 Strategy (2)'!M3+'1 Strategy (2)'!M5+'1 Strategy (2)'!M7+'1 Strategy (2)'!M9+'1 Strategy (2)'!M11 -> 6.25
B15: 2 – Specifications (details page 4 and page 5) | C15: =IF(F15,E15/F15,"Not applicable") -> 1 | E15: =SUM(G15:H15) -> 14 | F15: =SUM(I15:J15) -> 14 | G15: ='2 Specifications (1)'!L3+'2 Specifications (1)'!L5+'2 Specifications (1)'!L7+'2 Specifications (1)'!L9+'2 Specifications (1)'!L11 -> 7.25 | H15: ='2 Specifications (2)'!L3+'2 Specifications (2)'!L5+'2 Specifications (2)'!L7+'2 Specifications (2)'!L9+'2 Specifications (2)'!L11 -> 6.75 | I15: ='2 Specifications (1)'!M3+'2 Specifications (1)'!M5+'2 Specifications (1)'!M7+'2 Specifications (1)'!M9+'2 Specifications (1)'!M11 -> 7.25 | J15: ='2 Specifications (2)'!M3+'2 Specifications (2)'!M5+'2 Specifications (2)'!M7+'2 Specifications (2)'!M9+'2 Specifications (2)'!M11 -> 6.75
B16: 3 – Architecture (details page 6) | C16: =IF(F16,E16/F16,"Not applicable") -> 0.36363636 | E16: =SUM(G16:H16) -> 3 | F16: =SUM(I16:J16) -> 8.25 | G16: ='3 Architecture'!L3+'3 Architecture'!L5+'3 Architecture'!L7+'3 Architecture'!L9+'3 Architecture'!L11+'3 Architecture'!L13+'3 Architecture'!L15 -> 3 | I16: ='3 Architecture'!M3+'3 Architecture'!M5+'3 Architecture'!M7+'3 Architecture'!M9+'3 Architecture'!M11+'3 Architecture'!M13+'3 Architecture'!M15 -> 8.25
B17: 4 – User Experience and Interface (details page 7 and page 8) | C17: =IF(F17,E17/F17,"Not applicable") -> 0.30555556 | E17: =SUM(G17:H17) -> 5.5 | F17: =SUM(I17:J17) -> 18 | G17: ='4 UX UI (1)'!L3+'4 UX UI (1)'!L5+'4 UX UI (1)'!L7+'4 UX UI (1)'!L9+'4 UX UI (1)'!L11+'4 UX UI (1)'!L13+'4 UX UI (1)'!L15+'4 UX UI (1)'!L17 -> 4.25 | H17: ='4 UX UI (2)'!L3+'4 UX UI (2)'!L5+'4 UX UI (2)'!L7+'4 UX UI (2)'!L9+'4 UX UI (2)'!L11+'4 UX UI (2)'!L13+'4 UX UI (2)'!L15 -> 1.25 | I17: ='4 UX UI (1)'!M3+'4 UX UI (1)'!M5+'4 UX UI (1)'!M7+'4 UX UI (1)'!M9+'4 UX UI (1)'!M11+'4 UX UI (1)'!M13+'4 UX UI (1)'!M15+'4 UX UI (1)'!M17 -> 9.75 | J17: ='4 UX UI (2)'!M3+'4 UX UI (2)'!M5+'4 UX UI (2)'!M7+'4 UX UI (2)'!M9+'4 UX UI (2)'!M11+'4 UX UI (2)'!M13+'4 UX UI (2)'!M15 -> 8.25
B18: 5 – Content (details page 9) | C18: =IF(F18,E18/F18,"Not applicable") -> 0 | E18: =SUM(G18:H18) -> 0 | F18: =SUM(I18:J18) -> 3.25 | G18: ='5 Content'!L3+'5 Content'!L5+'5 Content'!L7+'5 Content'!L9+'5 Content'!L11+'5 Content'!L13+'5 Content'!L15+'5 Content'!L17 -> 0 | I18: ='5 Content'!M3+'5 Content'!M5+'5 Content'!M7+'5 Content'!M9+'5 Content'!M11+'5 Content'!M13+'5 Content'!M15+'5 Content'!M17 -> 3.25
B19: 6 – Frontend (details page 10) | C19: =IF(F19,E19/F19,"Not applicable") -> 0.46875 | E19: =SUM(G19:H19) -> 3.75 | F19: =SUM(I19:J19) -> 8 | G19: ='6 Frontend'!L3+'6 Frontend'!L5+'6 Frontend'!L7+'6 Frontend'!L9+'6 Frontend'!L11+'6 Frontend'!L13+'6 Frontend'!L15 -> 3.75 | I19: ='6 Frontend'!M3+'6 Frontend'!M5+'6 Frontend'!M7+'6 Frontend'!M9+'6 Frontend'!M11+'6 Frontend'!M13+'6 Frontend'!M15 -> 8
B20: 7 – Backend (details page 11) | C20: =IF(F20,E20/F20,"Not applicable") -> 0.35714286 | E20: =SUM(G20:H20) -> 1.25 | F20: =SUM(I20:J20) -> 3.5 | G20: ='7 Backend'!L3+'7 Backend'!L5+'7 Backend'!L7+'7 Backend'!L9 -> 1.25 | I20: ='7 Backend'!M3+'7 Backend'!M5+'7 Backend'!M7+'7 Backend'!M9 -> 3.5
B21: 8 – Hosting (details page 12 and page 13) | C21: =IF(F21,E21/F21,"Not applicable") -> 0.78571429 | E21: =SUM(G21:H21) -> 8.25 | F21: =SUM(I21:J21) -> 10.5 | G21: ='8 Hosting (1)'!L4+'8 Hosting (1)'!L6+'8 Hosting (1)'!L8+'8 Hosting (1)'!L10+'8 Hosting (1)'!L12 -> 5.75 | H21: ='8 Hosting (2)'!L3+'8 Hosting (2)'!L5+'8 Hosting (2)'!L7+'8 Hosting (2)'!L9+'8 Hosting (2)'!L11 -> 2.5 | I21: ='8 Hosting (1)'!M4+'8 Hosting (1)'!M6+'8 Hosting (1)'!M8+'8 Hosting (1)'!M10+'8 Hosting (1)'!M12 -> 5.75 | J21: ='8 Hosting (2)'!M3+'8 Hosting (2)'!M5+'8 Hosting (2)'!M7+'8 Hosting (2)'!M9+'8 Hosting (2)'!M11 -> 4.75
B22: 9 – Algorithmics (details page 14) | C22: =IF(F22,E22/F22,"Not applicable") -> 0.79310345 | E22: =SUM(G22:H22) -> 5.75 | F22: =SUM(I22:J22) -> 7.25 | G22: ='9 Algorithmics'!L3+'9 Algorithmics'!L5+'9 Algorithmics'!L7+'9 Algorithmics'!L9+'9 Algorithmics'!L11+'9 Algorithmics'!L13+'9 Algorithmics'!L15 -> 5.75 | I22: ='9 Algorithmics'!M3+'9 Algorithmics'!M5+'9 Algorithmics'!M7+'9 Algorithmics'!M9+'9 Algorithmics'!M11+'9 Algorithmics'!M13+'9 Algorithmics'!M15 -> 7.25
A24: Progress score from previous assessments No previous RGESN assessments have been conducted for this service. The Smart Library digital service aims to improve this progress score to 90% compliance in 2027. | E24: The progress score is calculated as follows: [SUM OF VALIDATED CRITERIA WITH WEIGHTING / TOTAL POINTS OF APPLICABLE CRITERIA WITH WEIGHTING ] x 100 i.e. : [ Number of validated ‘Top priority’ criteria x 1.5 + Number of validated ‘Recommended’ criteria x 1.25 + Number of validated ‘Moderate’ criteria / Number of validated and non-validated applicable ‘Top priority’ criteria x 1.5 + Number of validated and non-validated applicable ‘Recommended’ criteria x 1.25 + Number of validated and non-validated applicable ‘Moderate’ criteria ] x 100
A26: Progress plan for the digital service ecodesign approach In addition, the following courses of action have been or will be implemented: • Improve navigation efficiency (4.3) • Add notification preferences (4.13) • Define log retention periods (7.2) • Implement lightweight caching (9.7) To this end, reviews and audits are carried out every 12 months.
E27: .ods file (OpenDocument 1.3) created with LibreOffice Calc 7.6, on 6 May 2024 by Arcep.

Sheet 1 Strategy (1)
A1: The content of these columns is used to generate the PDF to be published (use the PDF export function in this software). | H1: Columns for internal use (not published in the generated PDF) Complete these boxes if this will help you to progress. | L1: Columns to help assess the criterion (not published in the generated PDF) and example of an ecodesign declaration
A2: ID | C2: Name of the criteria | D2: Level of priority | E2: Evaluation | F2: Date of Evaluation | G2: Potential developments | H2: Level of difficulty | I2: Actions to be taken | J2: Who does ? | K2: For when ? | L2: Score By ID | M2: Denominator | N2: Target | O2: Summary of the means of testing or checking (consult the RGESN for the full version)
A3: 1 – Stratégy (1/2) | B3: 1.1 | C3: Has the digital service been assessed favourably in terms of utility by taking its impact on the environment into account? | D3: Top priority | E3: Validated | F3: 15/11/2025 | G3: Improve documentation of environmental benefits and refine the comparison with non-digital alternatives. | H3: High | L3: =IFS(D3="Top priority",IFS(E3="Validated",1.5,E3="Ongoing",0,E3="Not validated",0,E3="Not applicable",0,E3="To evaluate",0),D3="Recommanded",IFS(E3="Validated",1.25,E3="Ongoing",0,E3="Not validated",0,E3="Not applicable",0,E3="To evaluate",0),D3="Moderate",IFS(E3="Validated",1,E3="Ongoing",0,E3="Not validated",0,E3="Not applicable",0,E3="To evaluate",0)) -> 1.5 | M3: =IFS(D3="Top priority",IFS(E3="Validated",1.5,E3="Ongoing",1.5,E3="Not validated",1.5,E3="Non applicable",0,E3="To evaluate",1.5),D3="Recommanded",IFS(E3="Validated",1.25,E3="Ongoing",1.25,E3="Not validated",1.25,E3="Non applicable",0,E3="To evaluate",1.25),D3="Moderate",IFS(E3="Validated",1,E3="Ongoing",1,E3="Not validated",1,E3="Non applicable",0,E3="To evaluate",1)) -> 1.5 | N3: Applicable to all services | O3: Utility was assessed using RGESN 1.1 guidelines: identification of SDGs, comparison with non-digital alternatives, confirmation of user needs, and validation that the service provides more value than the resources it consumes.
H4: The service Smart Library has been favourably assessed in terms of its utility, taking into account SDG 11 and SDG 12. Indeed, the service enables better use of study spaces, reduces unnecessary student movement, and limits energy waste by improving the management of room occupancy.
B5: 1.2 | C5: Has the digital service defined its target users, the target users’ actual job-related needs and expectations? | D5: Top priority | E5: Validated | F5: 15/11/2025 | G5: Conduct a more formal user survey to refine personas and confirm evolving needs. | H5: Low | L5: =IFS(D5="Top priority",IFS(E5="Validated",1.5,E5="Ongoing",0,E5="Not validated",0,E5="Not applicable",0,E5="To evaluate",0),D5="Recommanded",IFS(E5="Validated",1.25,E5="Ongoing",0,E5="Not validated",0,E5="Not applicable",0,E5="To evaluate",0),D5="Moderate",IFS(E5="Validated",1,E5="Ongoing",0,E5="Not validated",0,E5="Not applicable",0,E5="To evaluate",0)) -> 1.5 | M5: =IFS(D5="Top priority",IFS(E5="Validated",1.5,E5="Ongoing",1.5,E5="Not validated",1.5,E5="Not applicable",0,E5="To evaluate",1.5),D5="Recommanded",IFS(E5="Validated",1.25,E5="Ongoing",1.25,E5="Not validated",1.25,E5="Not applicable",0,E5="To evaluate",1.25),D5="Moderate",IFS(E5="Validated",1,E5="Ongoing",1,E5="Not validated",1,E5="Not applicable",0,E5="O7",1)) -> 1.5 | N5: Applicable to all services | O5: User needs were analysed through simple interviews and observation of real study-room usage patterns. This confirms that the target users and their expectations are well understood, satisfying RGESN 1.2 requirements.
H6: The service Smart Library has clearly identified its primary users (students) and secondary users (library staff). Their main need—quickly finding an available study room—was validated during project discussions and direct observation. The service design focuses only on features that respond to these needs.
B7: 1.3 | C7: Does the digital service have at least one identified ecodesign supervisor? | D7: Recommanded | E7: Validated | F7: 15/11/2025 | G7: Document the supervisor’s responsibilities more formally and update them each semester | H7: Low | L7: =IFS(D7="Top priority",IFS(E7="Validated",1.5,E7="Ongoing",0,E7="Not validated",0,E7="Not applicable",0,E7="To evaluate",0),D7="Recommanded",IFS(E7="Validated",1.25,E7="Ongoing",0,E7="Not validated",0,E7="Not applicable",0,E7="To evaluate",0),D7="Moderate",IFS(E7="Validated",1,E7="Ongoing",0,E7="Not validated",0,E7="Not applicable",0,E7="To evaluate",0)) -> 1.25 | M7: =IFS(D7="Top priority",IFS(E7="Validated",1.5,E7="Ongoing",1.5,E7="Not validated",1.5,E7="Not applicable",0,E7="To evaluate",1.5),D7="Recommanded",IFS(E7="Validated",1.25,E7="Ongoing",1.25,E7="Not validated",1.25,E7="Not applicable",0,E7="To evaluate",1.25),D7="Moderate",IFS(E7="Validated",1,E7="Ongoing",1,E7="Not validated",1,E7="Not applicable",0,E7="To evaluate",1)) -> 1.25 | N7: Applicable to all services | O7: Validation is based on naming the ecodesign supervisor in project documentation, in line with RGESN requirements. The role and responsibilities are recorded and accessible, fulfilling the need for a designated person to oversee ecodesign within the service.
H8: The service Smart Library has an identified ecodesign supervisor responsible for promoting sustainable practices during development. This role ensures consistency in ecodesign decisions and supports the team in applying RGESN best practices.
B9: 1.4 | C9: Does the digital service perform regular reviews to check the compliance of its ecodesign strategy? | D9: Top priority | E9: Validated | F9: 15/11/2025 | G9: Plan a simple annual ecodesign review to update the declaration and track improvements. | H9: Medium | L9: =IFS(D9="Top priority",IFS(E9="Validated",1.5,E9="Ongoing",0,E9="Not validated",0,E9="Not applicable",0,E9="To evaluate",0),D9="Recommanded",IFS(E9="Validated",1.25,E9="Ongoing",0,E9="Not validated",0,E9="Not applicable",0,E9="To evaluate",0),D9="Moderate",IFS(E9="Validated",1,E9="Ongoing",0,E9="Not validated",0,E9="Not applicable",0,E9="To evaluate",0)) -> 1.5 | M9: =IFS(D9="Top priority",IFS(E9="Validated",1.5,E9="Ongoing",1.5,E9="Not validated",1.5,E9="Not applicable",0,E9="To evaluate",1.5),D9="Recommanded",IFS(E9="Validated",1.25,E9="Ongoing",1.25,E9="Not validated",1.25,E9="Not applicable",0,E9="To evaluate",1.25),D9="Moderate",IFS(E9="Validated",1,E9="Ongoing",1,E9="Not validated",1,E9="Not applicable",0,E9="To evaluate",1)) -> 1.5 | N9: Applicable to all services | O9: Regular self-assessments based on the RGESN framework confirm compliance. Documentation of these reviews and updates to the ecodesign declaration satisfy the monitoring requirements.
H10: The service Smart Library performs informal reviews of its ecodesign practices during development, ensuring that resource use, performance, and sustainability targets remain aligned with RGESN principles.
B11: 1.5 | C11: Has the digital service set itself goals in terms of reducing or limiting its own environmental impacts? | D11: Top priority | E11: Validated | F11: 15/11/2025 | G11: Define simple measurable indicators (e.g., energy use per room monitored) for future tracking. | H11: High | L11: =IFS(D11="Top priority",IFS(E11="Validated",1.5,E11="Ongoing",0,E11="Not validated",0,E11="Not applicable",0,E11="To evaluate",0),D11="Recommanded",IFS(E11="Validated",1.25,E11="Ongoing",0,E11="Not validated",0,E11="Not applicable",0,E11="To evaluate",0),D11="Moderate",IFS(E11="Validated",1,E11="Ongoing",0,E11="Not validated",0,E11="Not applicable",0,E11="To evaluate",0)) -> 1.5 | M11: =IFS(D11="Top priority",IFS(E11="Validated",1.5,E11="Ongoing",1.5,E11="Not validated",1.5,E11="Not applicable",0,E11="To evaluate",1.5),D11="Recommanded",IFS(E11="Validated",1.25,E11="Ongoing",1.25,E11="Not validated",1.25,E11="Not applicable",0,E11="To evaluate",1.25),D11="Moderate",IFS(E11="Validated",1,E11="Ongoing",1,E11="Not validated",1,E11="Not applicable",0,E11="To evaluate",1)) -> 1.5 | N11: Applicable to all services | O11: Environmental considerations were reviewed during design, focusing on reduced energy waste in unused rooms and limiting data collection and processing. These goals align with RGESN expectations for defining and monitoring environmental impact objectives.
H12: The service Smart Library has set basic goals to reduce environmental impacts by optimising room usage, decreasing unnecessary lighting and heating, and limiting data processing to essential functions. These goals guide design choices toward lower energy and resource consumption.

Sheet 1 Strategy (2)
A1: The content of these columns is used to generate the PDF to be published (use the PDF export function in this software). | H1: Columns for internal use (not published in the generated PDF) Complete these boxes if this will help you to progress. | L1: Columns to help assess the criterion (not published in the generated PDF) and example of an ecodesign declaration
A2: ID | C2: Name of the criteria | D2: Level of priority | E2: Evaluation | F2: Date of Evaluation | G2: Potential developments | H2: Level of difficulty | I2: Actions to be taken | J2: Who does ? | K2: For when ? | L2: Score By ID | M2: Denominator | N2: Target | O2: Summary of the means of testing or checking (consult the RGESN for the full version)
A3: 1 – Stratégy (2/2) | B3: 1.6 | C3: Does the digital service collect data in a responsible and judicious manner? | D3: Recommanded | E3: Validated | F3: 15/11/2025 | G3: Review data collection annually to ensure no unnecessary new data types are added. | H3: Medium | L3: =IFS(D3="Top priority",IFS(E3="Validated",1.5,E3="Ongoing",0,E3="Not validated",0,E3="Not applicable",0,E3="To evaluate",0),D3="Recommanded",IFS(E3="Validated",1.25,E3="Ongoing",0,E3="Not validated",0,E3="Not applicable",0,E3="To evaluate",0),D3="Moderate",IFS(E3="Validated",1,E3="Ongoing",0,E3="Not validated",0,E3="Not applicable",0,E3="To evaluate",0)) -> 1.25 | M3: =IFS(D3="Top priority",IFS(E3="Validated",1.5,E3="Ongoing",1.5,E3="Not validated",1.5,E3="Not applicable",0,E3="To evaluate",1.5),D3="Recommanded",IFS(E3="Validated",1.25,E3="Ongoing",1.25,E3="Not validated",1.25,E3="Not applicable",0,E3="To evaluate",1.25),D3="Moderate",IFS(E3="Validated",1,E3="Ongoing",1,E3="Not validated",1,E3="Not applicable",0,E3="To evaluate",1)) -> 1.25 | N3: Applicable to all services | O3: Data flows were reviewed to verify that only strictly necessary information is stored or processed, with no profiling or unnecessary metadata. This meets RGESN expectations for responsible, minimized data collection.
H4: The service Smart Library collects only essential data (room occupancy signals and basic usage metrics). No personal data or tracking metadata are collected, ensuring minimal resource use and alignment with responsible data practices.
B5: 1.7 | C5: Does the digital service use an encryption level tailored to its needs? | D5: Moderate | E5: To evaluate | F5: 15/11/2025 | H5: Medium | L5: =IFS(D5="Top priority",IFS(E5="Validated",1.5,E5="Ongoing",0,E5="Not validated",0,E5="Not applicable",0,E5="To evaluate",0),D5="Recommanded",IFS(E5="Validated",1.25,E5="Ongoing",0,E5="Not validated",0,E5="Not applicable",0,E5="To evaluate",0),D5="Moderate",IFS(E5="Validated",1,E5="Ongoing",0,E5="Not validated",0,E5="Not applicable",0,E5="To evaluate",0)) -> 0 | M5: =IFS(D5="Top priority",IFS(E5="Validated",1.5,E5="Ongoing",1.5,E5="Not validated",1.5,E5="Not applicable",0,E5="To evaluate",1.5),D5="Recommanded",IFS(E5="Validated",1.25,E5="Ongoing",1.25,E5="Not validated",1.25,E5="Not applicable",0,E5="To evaluate",1.25),D5="Moderate",IFS(E5="Validated",1,E5="Ongoing",1,E5="Not validated",1,E5="Not applicable",0,E5="To evaluate",1)) -> 1 | N5: N/A if the service does not use an encryption mechanism | O5: If the service relies on encryption mechanisms, document the reasons for choosing to implement them in terms of the service’s IT security risks and the minimisation of the associated environmental footprint, in the service’s Ecodesign declaration of conformity.
H6: Cryptographic mechanisms have been put in place to ensure the security of the service's data. The choice was oriented towards [to be completed] technologies following an analysis of IT security risks for the service and of the associated environmental footprint, the public outlines of which are as follows: [to be detailed].
B7: 1.8 | C7: Has the digital service taken steps to embrace open source? | D7: Recommanded | E7: Validated | F7: 15/11/2025 | G7: Document which components could be migrated to open-source alternatives in future versions. | H7: High | L7: =IFS(D7="Top priority",IFS(E7="Validated",1.5,E7="Ongoing",0,E7="Not validated",0,E7="Not applicable",0,E7="To evaluate",0),D7="Recommanded",IFS(E7="Validated",1.25,E7="Ongoing",0,E7="Not validated",0,E7="Not applicable",0,E7="To evaluate",0),D7="Moderate",IFS(E7="Validated",1,E7="Ongoing",0,E7="Not validated",0,E7="Not applicable",0,E7="To evaluate",0)) -> 1.25 | M7: =IFS(D7="Top priority",IFS(E7="Validated",1.5,E7="Ongoing",1.5,E7="Not validated",1.5,E7="Not applicable",0,E7="To evaluate",1.5),D7="Recommanded",IFS(E7="Validated",1.25,E7="Ongoing",1.25,E7="Not validated",1.25,E7="Not applicable",0,E7="To evaluate",1.25),D7="Moderate",IFS(E7="Validated",1,E7="Ongoing",1,E7="Not validated",1,E7="Not applicable",0,E7="To evaluate",1)) -> 1.25 | N7: Applicable to all services | O7: The use of open-source tools is visible in the project’s technical documentation, meeting RGESN expectations for transparency and openness.
H8: The service Smart Library uses open-source technologies (e.g., frontend frameworks, backend libraries, and standard APIs). These choices reduce vendor lock-in and support long-term maintainability.
B9: 1.9 | C9: Has the digital service been designed using standard, interoperable technologies rather than dedicated, closed-source technologies? | D9: Top priority | E9: Validated | F9: 15/11/2025 | G9: Maintain interoperability by periodically reviewing dependencies for compatibility with industry standards. | H9: Medium | L9: =IFS(D9="Top priority",IFS(E9="Validated",1.5,E9="Ongoing",0,E9="Not validated",0,E9="Not applicable",0,E9="To evaluate",0),D9="Recommanded",IFS(E9="Validated",1.25,E9="Ongoing",0,E9="Not validated",0,E9="Not applicable",0,E9="To evaluate",0),D9="Moderate",IFS(E9="Validated",1,E9="Ongoing",0,E9="Not validated",0,E9="Not applicable",0,E9="To evaluate",0)) -> 1.5 | M9: =IFS(D9="Top priority",IFS(E9="Validated",1.5,E9="Ongoing",1.5,E9="Not validated",1.5,E9="Not applicable",0,E9="To evaluate",1.5),D9="Recommanded",IFS(E9="Validated",1.25,E9="Ongoing",1.25,E9="Not validated",1.25,E9="Not applicable",0,E9="To evaluate",1.25),D9="Moderate",IFS(E9="Validated",1,E9="Ongoing",1,E9="Not validated",1,E9="Not applicable",0,E9="To evaluate",1)) -> 1.5 | N9: Applicable to all services | O9: A review of the technical stack confirms that only open standards and widely supported protocols are used, aligning with RGESN requirements for interoperability.
H10: The service Smart Library is built using standard web technologies (HTML, CSS, JavaScript, REST APIs). No proprietary protocols are required, ensuring interoperability across devices and platforms.
B11: 1.10 | C11: Does the digital service use documented and open APIs to interact with the hardware? | D11: Recommanded | E11: Validated | F11: 15/11/2025 | G11: Continue using simple, documented browser APIs and avoid adding hardware-dependent features. | H11: High | L11: =IFS(D11="Top priority",IFS(E11="Validated",1.5,E11="Ongoing",0,E11="Not validated",0,E11="Not applicable",0,E11="To evaluate",0),D11="Recommanded",IFS(E11="Validated",1.25,E11="Ongoing",0,E11="Not validated",0,E11="Not applicable",0,E11="To evaluate",0),D11="Moderate",IFS(E11="Validated",1,E11="Ongoing",0,E11="Not validated",0,E11="Not applicable",0,E11="To evaluate",0)) -> 1.25 | M11: =IFS(D11="Top priority",IFS(E11="Validated",1.5,E11="Ongoing",1.5,E11="Not validated",1.5,E11="Not applicable",0,E11="To evaluate",1.5),D11="Recommanded",IFS(E11="Validated",1.25,E11="Ongoing",1.25,E11="Not validated",1.25,E11="Not applicable",0,E11="To evaluate",1.25),D11="Moderate",IFS(E11="Validated",1,E11="Ongoing",1,E11="Not validated",1,E11="Not applicable",0,E11="To evaluate",1)) -> 1.25 | N11: Applicable to all services | O11: Verification of the codebase shows that only documented browser and web APIs are used. No proprietary or device-specific interfaces are required, satisfying RGESN expectations.
H12: The service Smart Library does not rely on proprietary hardware APIs. Any interactions (e.g., display rendering, browser APIs) use standard and documented web interfaces, ensuring compatibility and transparency.

Sheet 2 Specifications (1)
A1: The content of these columns is used to generate the PDF to be published (use the PDF export function in this software). | H1: Columns for internal use (not published in the generated PDF) Complete these boxes if this will help you to progress. | L1: Columns to help assess the criterion (not published in the generated PDF) and example of an ecodesign declaration
A2: ID | C2: Name of the criteria | D2: Level of priority | E2: Evaluation | F2: Date of Evaluation | G2: Potential developments | H2: Level of difficulty | I2: Actions to be taken | J2: Who does ? | K2: For when ? | L2: Score By ID | M2: Denominator | N2: Target | O2: Summary of the means of testing or checking (consult the RGESN for the full version)
A3: 2 – Specifications (1/2) | B3: 2.1 | C3: Has the digital service drawn up a list of the hardware profiles that users will be able to employ to access it? | D3: Top priority | E3: Validated | F3: 15/11/2025 | G3: Refine the hardware list with more precise performance thresholds as the service evolves. | H3: Medium | L3: =IFS(D3="Top priority",IFS(E3="Validated",1.5,E3="Ongoing",0,E3="Not validated",0,E3="Not applicable",0,E3="To evaluate",0),D3="Recommanded",IFS(E3="Validated",1.25,E3="Ongoing",0,E3="Not validated",0,E3="Not applicable",0,E3="To evaluate",0),D3="Moderate",IFS(E3="Validated",1,E3="Ongoing",0,E3="Not validated",0,E3="Not applicable",0,E3="To evaluate",0)) -> 1.5 | M3: =IFS(D3="Top priority",IFS(E3="Validated",1.5,E3="Ongoing",1.5,E3="Not validated",1.5,E3="Not applicable",0,E3="To evaluate",1.5),D3="Recommanded",IFS(E3="Validated",1.25,E3="Ongoing",1.25,E3="Not validated",1.25,E3="Not applicable",0,E3="To evaluate",1.25),D3="Moderate",IFS(E3="Validated",1,E3="Ongoing",1,E3="Not validated",1,E3="Not applicable",0,E3="To evaluate",1)) -> 1.5 | N3: Applicable to all services | O3: The service was tested on typical student devices and a low-power display to confirm compatibility. The defined hardware profiles are listed and meet RGESN expectations for documenting supported device categories.
H4: The service Smart Library has defined the hardware profiles required to access it, including entry-level laptops, tablets, smartphones, and a low-power display for the dashboard. The service runs on common devices without requiring high-performance hardware
B5: 2.2 | C5: Can the digital service be used on older model devices? | D5: Top priority | E5: Validated | F5: 15/11/2025 | G5: Test performance on older laptops/tablets every semester to ensure continued compatibility. | H5: Medium | L5: =IFS(D5="Top priority",IFS(E5="Validated",1.5,E5="Ongoing",0,E5="Not validated",0,E5="Not applicable",0,E5="To evaluate",0),D5="Recommanded",IFS(E5="Validated",1.25,E5="Ongoing",0,E5="Not validated",0,E5="Not applicable",0,E5="To evaluate",0),D5="Moderate",IFS(E5="Validated",1,E5="Ongoing",0,E5="Not validated",0,E5="Not applicable",0,E5="To evaluate",0)) -> 1.5 | M5: =IFS(D5="Top priority",IFS(E5="Validated",1.5,E5="Ongoing",1.5,E5="Not validated",1.5,E5="Not applicable",0,E5="To evaluate",1.5),D5="Recommanded",IFS(E5="Validated",1.25,E5="Ongoing",1.25,E5="Not validated",1.25,E5="Not applicable",0,E5="To evaluate",1.25),D5="Moderate",IFS(E5="Validated",1,E5="Ongoing",1,E5="Not validated",1,E5="Not applicable",0,E5="To evaluate",1)) -> 1.5 | N5: Applicable to all services | O5: Tested on low-performance devices to confirm functionality of core features, satisfying the RGESN requirement to support older hardware.
H6: The service Smart Library runs smoothly on older laptops and standard student devices, as it relies on lightweight web technologies and simple UI elements.
B7: 2.3 | C7: Can the digital service be used with a low-speed connection or offline? | D7: Recommanded | E7: Validated | F7: 15/11/2025 | G7: Introduce a minimal “text-only” fallback view for extremely weak connections. | H7: Medium | L7: =IFS(D7="Top priority",IFS(E7="Validated",1.5,E7="Ongoing",0,E7="Not validated",0,E7="Not applicable",0,E7="To evaluate",0),D7="Recommanded",IFS(E7="Validated",1.25,E7="Ongoing",0,E7="Not validated",0,E7="Not applicable",0,E7="To evaluate",0),D7="Moderate",IFS(E7="Validated",1,E7="Ongoing",0,E7="Not validated",0,E7="Not applicable",0,E7="To evaluate",0)) -> 1.25 | M7: =IFS(D7="Top priority",IFS(E7="Validated",1.5,E7="Ongoing",1.5,E7="Not validated",1.5,E7="Not applicable",0,E7="To evaluate",1.5),D7="Recommanded",IFS(E7="Validated",1.25,E7="Ongoing",1.25,E7="Not validated",1.25,E7="Not applicable",0,E7="To evaluate",1.25),D7="Moderate",IFS(E7="Validated",1,E7="Ongoing",1,E7="Not validated",1,E7="Not applicable",0,E7="To evaluate",1)) -> 1.25 | N7: Applicable to all services | O7: Basic features were tested on slow connections to ensure acceptable loading times, meeting RGESN low-bandwidth expectations.
H8: The service Smart Library remains functional with low-speed connections because it loads minimal data and displays simple occupancy information.
B9: 2.4 | C9: Can the digital service be used with older versions of the operating system and web browsers? | D9: Top priority | E9: Validated | F9: 15/11/2025 | G9: Maintain browser compatibility testing as new updates are released. | H9: Medium | L9: =IFS(D9="Top priority",IFS(E9="Validated",1.5,E9="Ongoing",0,E9="Not validated",0,E9="Not applicable",0,E9="To evaluate",0),D9="Recommanded",IFS(E9="Validated",1.25,E9="Ongoing",0,E9="Not validated",0,E9="Not applicable",0,E9="To evaluate",0),D9="Moderate",IFS(E9="Validated",1,E9="Ongoing",0,E9="Not validated",0,E9="Not applicable",0,E9="To evaluate",0)) -> 1.5 | M9: =IFS(D9="Top priority",IFS(E9="Validated",1.5,E9="Ongoing",1.5,E9="Not validated",1.5,E9="Not applicable",0,E9="To evaluate",1.5),D9="Recommanded",IFS(E9="Validated",1.25,E9="Ongoing",1.25,E9="Not validated",1.25,E9="Not applicable",0,E9="To evaluate",1.25),D9="Moderate",IFS(E9="Validated",1,E9="Ongoing",1,E9="Not validated",1,E9="Not applicable",0,E9="To evaluate",1)) -> 1.5 | N9: Applicable to all services | O9: Compatibility verified using older browser versions and common university devices.
H10: The service Smart Library uses standard browser features and avoids modern, unsupported APIs, ensuring compatibility with older OS and browser versions.
B11: 2.5 | C11: Does the digital service adapt to different types of display devices? | D11: Top priority | E11: Validated | F11: 15/11/2025 | G11: Improve responsive layout for very small screens. | H11: Medium | L11: =IFS(D11="Top priority",IFS(E11="Validated",1.5,E11="Ongoing",0,E11="Not validated",0,E11="Not applicable",0,E11="To evaluate",0),D11="Recommanded",IFS(E11="Validated",1.25,E11="Ongoing",0,E11="Not validated",0,E11="Not applicable",0,E11="To evaluate",0),D11="Moderate",IFS(E11="Validated",1,E11="Ongoing",0,E11="Not validated",0,E11="Not applicable",0,E11="To evaluate",0)) -> 1.5 | M11: =IFS(D11="Top priority",IFS(E11="Validated",1.5,E11="Ongoing",1.5,E11="Not validated",1.5,E11="Not applicable",0,E11="To evaluate",1.5),D11="Recommanded",IFS(E11="Validated",1.25,E11="Ongoing",1.25,E11="Not validated",1.25,E11="Not applicable",0,E11="To evaluate",1.25),D11="Moderate",IFS(E11="Validated",1,E11="Ongoing",1,E11="Not validated",1,E11="Not applicable",0,E11="To evaluate",1)) -> 1.5 | N11: Applicable to all services | O11: Checked UI layout on multiple screen sizes to confirm consistent readability and usability.
H12: The service Smart Library adapts to various displays, including wall screens, laptops, tablets, and smartphones, through responsive web design.

Sheet 2 Specifications (2)
A1: The content of these columns is used to generate the PDF to be published (use the PDF export function in this software). | H1: Columns for internal use (not published in the generated PDF) Complete these boxes if this will help you to progress. | L1: Columns to help assess the criterion (not published in the generated PDF) and example of an ecodesign declaration
A2: ID | C2: Name of the criteria | D2: Level of priority | E2: Evaluation | F2: Date of Evaluation | G2: Potential developments | H2: Level of difficulty | I2: Actions to be taken | J2: Who does ? | K2: For when ? | L2: Score By ID | M2: Denominator | N2: Target | O2: Summary of the means of testing or checking (consult the RGESN for the full version)
A3: 2 – Specifications (2/2) | B3: 2.6 | C3: Has the digital service planned for a design review and a code review whose goals include reducing each feature’s environmental impacts? | D3: Recommanded | E3: Validated | F3: 15/11/2025 | G3: Add lightweight performance checks to the design review process. | H3: Medium | L3: =IFS(D3="Top priority",IFS(E3="Validated",1.5,E3="Ongoing",0,E3="Not validated",0,E3="Not applicable",0,E3="To evaluate",0),D3="Recommanded",IFS(E3="Validated",1.25,E3="Ongoing",0,E3="Not validated",0,E3="Not applicable",0,E3="To evaluate",0),D3="Moderate",IFS(E3="Validated",1,E3="Ongoing",0,E3="Not validated",0,E3="Not applicable",0,E3="To evaluate",0)) -> 1.25 | M3: =IFS(D3="Top priority",IFS(E3="Validated",1.5,E3="Ongoing",1.5,E3="Not validated",1.5,E3="Not applicable",0,E3="To evaluate",1.5),D3="Recommanded",IFS(E3="Validated",1.25,E3="Ongoing",1.25,E3="Not validated",1.25,E3="Not applicable",0,E3="To evaluate",1.25),D3="Moderate",IFS(E3="Validated",1,E3="Ongoing",1,E3="Not validated",1,E3="Not applicable",0,E3="To evaluate",1)) -> 1.25 | N3: Applicable to all services | O3: Verification that essential features are minimal and efficient aligns with RGESN expectations for design/code review.
H4: The service Smart Library underwent informal design and code reviews prioritizing simplicity and low resource use for its core features.
B5: 2.7 | C5: Has the digital service planned for a maintenance and decommissioning strategy? | D5: Top priority | E5: Validated | F5: 15/11/2025 | G5: Document a simple long-term data retention policy. | H5: Medium | L5: =IFS(D5="Top priority",IFS(E5="Validated",1.5,E5="Ongoing",0,E5="Not validated",0,E5="Not applicable",0,E5="To evaluate",0),D5="Recommanded",IFS(E5="Validated",1.25,E5="Ongoing",0,E5="Not validated",0,E5="Not applicable",0,E5="To evaluate",0),D5="Moderate",IFS(E5="Validated",1,E5="Ongoing",0,E5="Not validated",0,E5="Not applicable",0,E5="To evaluate",0)) -> 1.5 | M5: =IFS(D5="Top priority",IFS(E5="Validated",1.5,E5="Ongoing",1.5,E5="Not validated",1.5,E5="Not applicable",0,E5="To evaluate",1.5),D5="Recommanded",IFS(E5="Validated",1.25,E5="Ongoing",1.25,E5="Not validated",1.25,E5="Not applicable",0,E5="To evaluate",1.25),D5="Moderate",IFS(E5="Validated",1,E5="Ongoing",1,E5="Not validated",1,E5="Not applicable",0,E5="To evaluate",1)) -> 1.5 | N5: Applicable to all services | O5: The maintenance approach and the ease of removing or updating components satisfy RGESN criteria for long-term planning.
H6: The service Smart Library has a basic maintenance strategy relying on standard web technologies, making updates and future decommissioning simple and low impact.
B7: 2.8 | C7: Does the digital service require its suppliers to guarantee a strategy to reduce their environmental impacts? | D7: Top priority | E7: Validated | F7: 15/11/2025 | G7: Reference the sustainability commitments of any third-party tools used. | H7: High | L7: =IFS(D7="Top priority",IFS(E7="Validated",1.5,E7="Ongoing",0,E7="Not validated",0,E7="Not applicable",0,E7="To evaluate",0),D7="Recommanded",IFS(E7="Validated",1.25,E7="Ongoing",0,E7="Not validated",0,E7="Not applicable",0,E7="To evaluate",0),D7="Moderate",IFS(E7="Validated",1,E7="Ongoing",0,E7="Not validated",0,E7="Not applicable",0,E7="To evaluate",0)) -> 1.5 | M7: =IFS(D7="Top priority",IFS(E7="Validated",1.5,E7="Ongoing",1.5,E7="Not validated",1.5,E7="Not applicable",0,E7="To evaluate",1.5),D7="Recommanded",IFS(E7="Validated",1.25,E7="Ongoing",1.25,E7="Not validated",1.25,E7="Not applicable",0,E7="To evaluate",1.25),D7="Moderate",IFS(E7="Validated",1,E7="Ongoing",1,E7="Not validated",1,E7="Not applicable",0,E7="To evaluate",1)) -> 1.5 | N7: Applicable to all services | O7: Supplier documentation was checked to confirm sustainability practices, matching RGESN expectations.
H8: The service Smart Library relies on university-managed infrastructure and widely used open-source tools whose maintainers publish sustainability and resource-efficiency commitments.
B9: 2.9 | C9: Has the digital service considered the environmental impacts of the off-the-shelf interface components used? | D9: Moderate | E9: Validated | F9: 15/11/2025 | G9: Keep UI libraries minimal and regularly remove unused components. | H9: High | L9: =IFS(D9="Top priority",IFS(E9="Validated",1.5,E9="Ongoing",0,E9="Not validated",0,E9="Not applicable",0,E9="To evaluate",0),D9="Recommanded",IFS(E9="Validated",1.25,E9="Ongoing",0,E9="Not validated",0,E9="Not applicable",0,E9="To evaluate",0),D9="Moderate",IFS(E9="Validated",1,E9="Ongoing",0,E9="Not validated",0,E9="Not applicable",0,E9="To evaluate",0)) -> 1 | M9: =IFS(D9="Top priority",IFS(E9="Validated",1.5,E9="Ongoing",1.5,E9="Not validated",1.5,E9="Not applicable",0,E9="To evaluate",1.5),D9="Recommanded",IFS(E9="Validated",1.25,E9="Ongoing",1.25,E9="Not validated",1.25,E9="Not applicable",0,E9="To evaluate",1.25),D9="Moderate",IFS(E9="Validated",1,E9="Ongoing",1,E9="Not validated",1,E9="Not applicable",0,E9="To evaluate",1)) -> 1 | N9: Applicable to all services | O9: Code inspection confirmed that minimal UI components are used, in line with RGESN recommendations.
H10: The service Smart Library uses lightweight interface components and avoids heavy UI libraries, reducing client-side resource use.
B11: 2.10 | C11: Has the digital service considered the environmental impacts of third-party services used when selecting them? | D11: Top priority | E11: Validated | F11: 15/11/2025 | G11: Periodically re-evaluate whether any external services can be replaced with lighter alternatives. | H11: High | L11: =IFS(D11="Top priority",IFS(E11="Validated",1.5,E11="Ongoing",0,E11="Not validated",0,E11="Not applicable",0,E11="To evaluate",0),D11="Recommanded",IFS(E11="Validated",1.25,E11="Ongoing",0,E11="Not validated",0,E11="Not applicable",0,E11="To evaluate",0),D11="Moderate",IFS(E11="Validated",1,E11="Ongoing",0,E11="Not validated",0,E11="Not applicable",0,E11="To evaluate",0)) -> 1.5 | M11: =IFS(D11="Top priority",IFS(E11="Validated",1.5,E11="Ongoing",1.5,E11="Not validated",1.5,E11="Not applicable",0,E11="To evaluate",1.5),D11="Recommanded",IFS(E11="Validated",1.25,E11="Ongoing",1.25,E11="Not validated",1.25,E11="Not applicable",0,E11="To evaluate",1.25),D11="Moderate",IFS(E11="Validated",1,E11="Ongoing",1,E11="Not validated",1,E11="Not applicable",0,E11="To evaluate",1)) -> 1.5 | N11: Applicable to all services | O11: Third-party services were reviewed to ensure they do not introduce unnecessary processing, aligning with RGESN selection guidelines.
H12: The service Smart Library relies on minimal external services, and chosen third-party tools were selected for reliability and low overhead.

Sheet 3 Architecture
A1: The content of these columns is used to generate the PDF to be published (use the PDF export function in this software). | H1: Columns for internal use (not published in the generated PDF) Complete these boxes if this will help you to progress. | L1: Columns to help assess the criterion (not published in the generated PDF) and example of an ecodesign declaration
A2: ID | C2: Name of the criteria | D2: Level of priority | E2: Evaluation | F2: Date of Evaluation | G2: Potential developments | H2: Level of difficulty | I2: Actions to be taken | J2: Who does ? | K2: For when ? | L2: Score By ID | M2: Denominator | N2: Target | O2: Summary of the means of testing or checking (consult the RGESN for the full version)
A3: 3 – Architecture | B3: 3.1 | C3: Is the digital service based on an architecture, resources and components designed to reduce their own environmental impacts? | D3: Top priority | E3: Validated | F3: 15/11/2025 | G3: Further simplify data flows to avoid any unnecessary requests. | H3: High | L3: 1.5 | M3: 1.5 | N3: Applicable to all services | O3: The architecture was reviewed to confirm that only essential components are deployed and that no heavy or unnecessary services are used.
H4: The service Smart Library uses a lightweight web architecture, with minimal backend logic and small data exchanges (only room occupancy and basic metadata), reducing computing and network usage.
B5: 3.2 | C5: Does the digital service run on an architecture that can tailor resource use to the service’s consumption? | D5: Recommanded | E5: Ongoing | F5: 15/11/2025 | G5: Introduce simple monitoring to better observe resource consumption as usage grows. | H5: High | I5: Set up simple logging or metrics to monitor request volume and resource usage. | J5: Developer or system administrator. | K5: Next technical iteration. | L5: 0 | M5: 1.25 | N5: Applicable to all services | O5: Basic analysis of request patterns shows that computation and data transfers happen mainly when users consult the dashboard.
H6: Smart Library processes only user-triggered requests (e.g. viewing room occupancy), so resource use already follows real usage, but monitoring could be improved.
B7: 3.3 | C7: Can the digital service support protocols’ ongoing technical development? | D7: Moderate | E7: To evaluate | F7: 15/11/2025 | H7: Medium | L7: =IFS(D7="Top priority",IFS(E7="Validated",1.5,E7="Ongoing",0,E7="Not validated",0,E7="Not applicable",0,E7="To evaluate",0),D7="Recommanded",IFS(E7="Validated",1.25,E7="Ongoing",0,E7="Not validated",0,E7="Not applicable",0,E7="To evaluate",0),D7="Moderate",IFS(E7="Validated",1,E7="Ongoing",0,E7="Not validated",0,E7="Not applicable",0,E7="To evaluate",0)) -> 0 | M7: =IFS(D7="Top priority",IFS(E7="Validated",1.5,E7="Ongoing",1.5,E7="Not validated",1.5,E7="Not applicable",0,E7="To evaluate",1.5),D7="Recommanded",IFS(E7="Validated",1.25,E7="Ongoing",1.25,E7="Not validated",1.25,E7="Not applicable",0,E7="To evaluate",1.25),D7="Moderate",IFS(E7="Validated",1,E7="Ongoing",1,E7="Not validated",1,E7="Not applicable",0,E7="To evaluate",1)) -> 1 | N7: N/A if the digital service does not use an internet connection | O7: Check that the digital service’s various components are working properly: • in IPv6 and do not use any IPv4-only service, and that the service uses DNS names and not hard coded IP addresses; • in HTTPS and not HTTP; • verify that the latest version of TLS (at the time of writing this policy framework: TLS v1.3) is properly supported. • Assess the adequacy of the protocol used in relation to the content being transferred, taking into account its environmental footprint. The criterion is validated if the choice of protocol used by the service aligns with the type of content and features targeted, while minimising its environmental cost, and is documented, if possible, in the Ecodesign declaration of conformity
H8: In order to prevent the risk of obsolescence and limit the need for updates/upgrades, the digital service is based on robust protocols that are adapted to its features. In particular: # examples # • The digital service is available in IPV6 (and IPV4) • The digital service is based on the HTTPS protocol • The version of TLS used must support the most recent version, i.e. [to be completed - at the time of writing, it is: TLS v1.3] [etc]
B9: 3.4 | C9: Does the digital service guarantee the supply of patch updates throughout the entire expected lifespan of the devices and software tied to the service? | D9: Top priority | E9: Validated | F9: 15/11/2025 | G9: Maintain a short change log describing applied patches. | H9: Medium | L9: 1.5 | M9: 1.5 | N9: Applicable to all services | O9: The update process was examined and confirms that fixes can be deployed centrally, independently of user hardware lifespan.
H10: As a web-based service, Smart Library can receive security and maintenance patches directly on the server without requiring users to update their devices or install new versions.
B11: 3.5 | C11: Does the digital service provide the ability to install patch updates independently of features updates, in a transparent fashion? | D11: Moderate | E11: To evaluate | F11: 15/11/2025 | H11: Medium | L11: =IFS(D11="Top priority",IFS(E11="Validated",1.5,E11="Ongoing",0,E11="Not validated",0,E11="Not applicable",0,E11="To evaluate",0),D11="Recommanded",IFS(E11="Validated",1.25,E11="Ongoing",0,E11="Not validated",0,E11="Not applicable",0,E11="To evaluate",0),D11="Moderate",IFS(E11="Validated",1,E11="Ongoing",0,E11="Not validated",0,E11="Not applicable",0,E11="To evaluate",0)) -> 0 | M11: =IFS(D11="Top priority",IFS(E11="Validated",1.5,E11="Ongoing",1.5,E11="Not validated",1.5,E11="Not applicable",0,E11="To evaluate",1.5),D11="Recommanded",IFS(E11="Validated",1.25,E11="Ongoing",1.25,E11="Not validated",1.25,E11="Not applicable",0,E11="To evaluate",1.25),D11="Moderate",IFS(E11="Validated",1,E11="Ongoing",1,E11="Not validated",1,E11="Not applicable",0,E11="To evaluate",1)) -> 1 | N11: N/A if the digital service does not provide (nonessential) features updates | O11: To validate this criterion: • Indicate in an application's update description (changelog) when it is a security or maintenance update ("hotfixes") or if it is a rolling update that adds functionality. • Ensure that features updates that are not critical to service compliance do not prevent the service from operating for any maintenance period for supported operating systems. • Whenever possible, ensure that updates that are essential to the digital service or user device’s compliance and security can be installed separately from features updates that are not necessary for the product’s compliance. • If possible, check for the presence of a release management strategy with “Long term support” releases.
B13: 3.6 | C13: Does the digital service offer incremental updates, to avoid replacing the entire code with each update? | D13: Moderate | E13: To evaluate | F13: 15/11/2025 | H13: Medium | L13: =IFS(D13="Top priority",IFS(E13="Validated",1.5,E13="Ongoing",0,E13="Not validated",0,E13="Not applicable",0,E13="To evaluate",0),D13="Recommanded",IFS(E13="Validated",1.25,E13="Ongoing",0,E13="Not validated",0,E13="Not applicable",0,E13="To evaluate",0),D13="Moderate",IFS(E13="Validated",1,E13="Ongoing",0,E13="Not validated",0,E13="Not applicable",0,E13="To evaluate",0)) -> 0 | M13: =IFS(D13="Top priority",IFS(E13="Validated",1.5,E13="Ongoing",1.5,E13="Not validated",1.5,E13="Not applicable",0,E13="To evaluate",1.5),D13="Recommanded",IFS(E13="Validated",1.25,E13="Ongoing",1.25,E13="Not validated",1.25,E13="Not applicable",0,E13="To evaluate",1.25),D13="Moderate",IFS(E13="Validated",1,E13="Ongoing",1,E13="Not validated",1,E13="Not applicable",0,E13="To evaluate",1)) -> 1 | N13: N/A if the digital service does not provide updates | O13: Whenever possible, use an update mechanism that does not require replacing the program’s entire code with each update. If necessary, a full update of the program code can be provided for "reset" or "self-healing" features. The criterion is validated if incremental updates are favoured for the digital service, aside from "reset" and "self-healing" features.
B15: 3.7 | C15: Does the digital service optimise the use of development, preproduction and test environments according to its needs? | D15: Moderate | E15: To evaluate | F15: 15/11/2025 | H15: Medium | L15: =IFS(D15="Top priority",IFS(E15="Validated",1.5,E15="Ongoing",0,E15="Not validated",0,E15="Not applicable",0,E15="To evaluate",0),D15="Recommanded",IFS(E15="Validated",1.25,E15="Ongoing",0,E15="Not validated",0,E15="Not applicable",0,E15="To evaluate",0),D15="Moderate",IFS(E15="Validated",1,E15="Ongoing",0,E15="Not validated",0,E15="Not applicable",0,E15="To evaluate",0)) -> 0 | M15: =IFS(D15="Top priority",IFS(E15="Validated",1.5,E15="Ongoing",1.5,E15="Not validated",1.5,E15="Not applicable",0,E15="To evaluate",1.5),D15="Recommanded",IFS(E15="Validated",1.25,E15="Ongoing",1.25,E15="Not validated",1.25,E15="Not applicable",0,E15="To evaluate",1.25),D15="Moderate",IFS(E15="Validated",1,E15="Ongoing",1,E15="Not validated",1,E15="Not applicable",0,E15="To evaluate",1)) -> 1 | N15: N/A if the digital service does not use a server | O15: The criterion is validated if the service relies on multi-tenant development/pre-production/test environments, or if these environments are disabled during time slots when they are not used. Indicate the choices made to limit the resources used by the development, pre-production or test environments in the digital service’s Ecodesign declaration of conformity.
H16: Development, pre-production or test environments are disabled at night, during the periods when they are not in use / the digital service rely on multi-tenant development, pre-production or test environments. [to be detailed]

Sheet 4 UX UI (1)
A1: The content of these columns is used to generate the PDF to be published (use the PDF export function in this software). | H1: Columns for internal use (not published in the generated PDF) Complete these boxes if this will help you to progress. | L1: Columns to help assess the criterion (not published in the generated PDF) and example of an ecodesign declaration
A2: ID | C2: Name of the criteria | D2: Level of priority | E2: Evaluation | F2: Date of Evaluation | G2: Potential developments | H2: Level of difficulty | I2: Actions to be taken | J2: Who does ? | K2: For when ? | L2: Score By ID | M2: Denominator | N2: Target | O2: Summary of the means of testing or checking (consult the RGESN for the full version)
A3: 4 – User Experience and Interface (1/2) | B3: 4.1 | C3: Does the digital service only have animations, videos and sounds whose automatic playback is disabled? | D3: Top priority | E3: Validated | F3: 15/11/2025 | G3: Ensure no future UI elements autoplay media. | H3: Low | L3: =IFS(D3="Top priority",IFS(E3="Validated",1.5,E3="Ongoing",0,E3="Not validated",0,E3="Not applicable",0,E3="To evaluate",0),D3="Recommanded",IFS(E3="Validated",1.25,E3="Ongoing",0,E3="Not validated",0,E3="Not applicable",0,E3="To evaluate",0),D3="Moderate",IFS(E3="Validated",1,E3="Ongoing",0,E3="Not validated",0,E3="Not applicable",0,E3="To evaluate",0)) -> 1.5 | M3: =IFS(D3="Top priority",IFS(E3="Validated",1.5,E3="Ongoing",1.5,E3="Not validated",1.5,E3="Not applicable",0,E3="To evaluate",1.5),D3="Recommanded",IFS(E3="Validated",1.25,E3="Ongoing",1.25,E3="Not validated",1.25,E3="Not applicable",0,E3="To evaluate",1.25),D3="Moderate",IFS(E3="Validated",1,E3="Ongoing",1,E3="Not validated",1,E3="Not applicable",0,E3="To evaluate",1)) -> 1.5 | N3: Applicable to all services | O3: UI review confirms no autoplay elements.
H4: Smart Library includes no videos, sounds, or animations that autoplay.
B5: 4.2 | C5: Does the digital service only display content without infinite scroll? | D5: Top priority | E5: Validated | F5: 15/11/2025 | G5: Avoid adding long lists that require dynamic scrolling. | H5: Medium | L5: =IFS(D5="Top priority",IFS(E5="Validated",1.5,E5="Ongoing",0,E5="Not validated",0,E5="Not applicable",0,E5="To evaluate",0),D5="Recommanded",IFS(E5="Validated",1.25,E5="Ongoing",0,E5="Not validated",0,E5="Not applicable",0,E5="To evaluate",0),D5="Moderate",IFS(E5="Validated",1,E5="Ongoing",0,E5="Not validated",0,E5="Not applicable",0,E5="To evaluate",0)) -> 1.5 | M5: =IFS(D5="Top priority",IFS(E5="Validated",1.5,E5="Ongoing",1.5,E5="Not validated",1.5,E5="Not applicable",0,E5="To evaluate",1.5),D5="Recommanded",IFS(E5="Validated",1.25,E5="Ongoing",1.25,E5="Not validated",1.25,E5="Not applicable",0,E5="To evaluate",1.25),D5="Moderate",IFS(E5="Validated",1,E5="Ongoing",1,E5="Not validated",1,E5="Not applicable",0,E5="To evaluate",1)) -> 1.5 | N5: Applicable to all services | O5: Screens were checked to confirm the absence of infinite scrolling.
H6: The dashboard shows static information without scrolling lists.
B7: 4.3 | C7: Does the digital service optimise the clickstream for each main feature? | D7: Recommanded | E7: Ongoing | F7: 15/11/2025 | G7: Simplify navigation to reduce the number of steps to access each room. | H7: Medium | I7: Review and reduce unnecessary steps. | J7: Frontend or UX/UI developer. | K7: Next iteration. | L7: =IFS(D7="Top priority",IFS(E7="Validated",1.5,E7="Ongoing",0,E7="Not validated",0,E7="Not applicable",0,E7="To evaluate",0),D7="Recommanded",IFS(E7="Validated",1.25,E7="Ongoing",0,E7="Not validated",0,E7="Not applicable",0,E7="To evaluate",0),D7="Moderate",IFS(E7="Validated",1,E7="Ongoing",0,E7="Not validated",0,E7="Not applicable",0,E7="To evaluate",0)) -> 0 | M7: =IFS(D7="Top priority",IFS(E7="Validated",1.5,E7="Ongoing",1.5,E7="Not validated",1.5,E7="Not applicable",0,E7="To evaluate",1.5),D7="Recommanded",IFS(E7="Validated",1.25,E7="Ongoing",1.25,E7="Not validated",1.25,E7="Not applicable",0,E7="To evaluate",1.25),D7="Moderate",IFS(E7="Validated",1,E7="Ongoing",1,E7="Not validated",1,E7="Not applicable",0,E7="To evaluate",1)) -> 1.25 | N7: Applicable to all services | O7: Walkthroughs show short paths with room for improvement.
H8: The navigation is simple, but some flows can be shortened.
B9: 4.4 | C9: Does the digital service give users the ability to enable a thirdparty service? | D9: Recommanded | E9: Not validated | F9: 15/11/2025 | G9: Add toggles if optional external services appear in future versions. | H9: Low | I9: None (not in project scope). | L9: =IFS(D9="Top priority",IFS(E9="Validated",1.5,E9="Ongoing",0,E9="Not validated",0,E9="Not applicable",0,E9="To evaluate",0),D9="Recommanded",IFS(E9="Validated",1.25,E9="Ongoing",0,E9="Not validated",0,E9="Not applicable",0,E9="To evaluate",0),D9="Moderate",IFS(E9="Validated",1,E9="Ongoing",0,E9="Not validated",0,E9="Not applicable",0,E9="To evaluate",0)) -> 0 | M9: =IFS(D9="Top priority",IFS(E9="Validated",1.5,E9="Ongoing",1.5,E9="Not validated",1.5,E9="Not applicable",0,E9="To evaluate",1.5),D9="Recommanded",IFS(E9="Validated",1.25,E9="Ongoing",1.25,E9="Not validated",1.25,E9="Not applicable",0,E9="To evaluate",1.25),D9="Moderate",IFS(E9="Validated",1,E9="Ongoing",1,E9="Not validated",1,E9="Not applicable",0,E9="To evaluate",1)) -> 1.25 | N9: Applicable to all services | O9: Code review confirms no user-controlled third-party services.
H10: Smart Library integrates no optional third-party services, so users cannot enable or disable any.
B11: 4.5 | C11: Does the digital service use mainly functional components that are native to the operating system, browser or language used? | D11: Moderate | E11: To evaluate | F11: 15/11/2025 | H11: Medium | L11: =IFS(D11="Top priority",IFS(E11="Validated",1.5,E11="Ongoing",0,E11="Not validated",0,E11="Not applicable",0,E11="To evaluate",0),D11="Recommanded",IFS(E11="Validated",1.25,E11="Ongoing",0,E11="Not validated",0,E11="Not applicable",0,E11="To evaluate",0),D11="Moderate",IFS(E11="Validated",1,E11="Ongoing",0,E11="Not validated",0,E11="Not applicable",0,E11="To evaluate",0)) -> 0 | M11: =IFS(D11="Top priority",IFS(E11="Validated",1.5,E11="Ongoing",1.5,E11="Not validated",1.5,E11="Not applicable",0,E11="To evaluate",1.5),D11="Recommanded",IFS(E11="Validated",1.25,E11="Ongoing",1.25,E11="Not validated",1.25,E11="Not applicable",0,E11="To evaluate",1.25),D11="Moderate",IFS(E11="Validated",1,E11="Ongoing",1,E11="Not validated",1,E11="Not applicable",0,E11="To evaluate",1)) -> 1 | N11: Applicable to all services | O11: The criterion is validated if the service favours the use of native functional components where possible. Furthermore, in the event of the use of non-native components, assess the need to have chosen to use such components (technical constraints, for instance). If applicable, document the reasons for using them in the Ecodesign declaration of conformity. Their use should be regularly monitored by verifying the content of the resources loaded and their actual use.
H12: The digital service interface is based mainly on functional components. The use of non-native components is justified in terms of [to be completed].
